<?xml version="1.0" ?>
<!-- Generated using onshape-to-robot -->
<!-- Onshape https://cad.onshape.com/documents/d578f2fbdc332270e30f24e5/w/ba84a5b38e318fd89e8c140d/e/9356b596fb5246da0639ba81 -->
<mujoco model="d:\USC\Proyectos\LaberintIA\LaberintIA_FrameWork\model">
  <compiler angle="radian" meshdir="assets" autolimits="false"/>
  <default>
    <default class="d:\USC\Proyectos\LaberintIA\LaberintIA_FrameWork\model">
      <joint frictionloss="0.1" armature="0.005"/>
      <position kp="50" dampratio="1"/>
      <default class="visual">
        <geom type="mesh" contype="0" conaffinity="0" group="2"/>
      </default>
      <default class="collision">
        <geom group="3"/>
      </default>
    </default>
  </default>
  <worldbody>
    <!-- Link base -->
    <body name="base" pos="0 0 0" quat="1 0 0 0" childclass="d:\USC\Proyectos\LaberintIA\LaberintIA_FrameWork\model">
      <freejoint name="base_freejoint"/>
      <inertial pos="0.0280351 -0.00916079 -0.0142167" mass="0.067095" fullinertia="9.9198e-05 5.77969e-05 0.000149749 -2.2884e-05 -1.83125e-06 2.1007e-08"/>
      <!-- Part hc_l -->
      <geom type="mesh" class="visual" pos="0.0245117 -0.0107575 -0.0202142" quat="0.707107 0 -0 -0.707107" mesh="hc_l" material="hc_l_material"/>
      <geom type="mesh" class="collision" pos="0.0245117 -0.0107575 -0.0202142" quat="0.707107 0 -0 -0.707107" mesh="hc_l" material="hc_l_material"/>
      <!-- Part part_1 -->
      <geom type="mesh" class="visual" pos="-0.0398296 -0.0723763 -0.0222142" quat="0 0 -1 -0" mesh="part_1" material="part_1_material"/>
      <geom type="mesh" class="collision" pos="-0.0398296 -0.0723763 -0.0222142" quat="0 0 -1 -0" mesh="part_1" material="part_1_material"/>
      <!-- Part part_1_2 -->
      <geom type="mesh" class="visual" pos="0.0818875 0.052487 -0.0472142" quat="1 0 0 0" mesh="part_1" material="part_1_material"/>
      <geom type="mesh" class="collision" pos="0.0818875 0.052487 -0.0472142" quat="1 0 0 0" mesh="part_1" material="part_1_material"/>
      <!-- Part hc_r -->
      <geom type="mesh" class="visual" pos="0.0189667 -0.00869755 -0.0202142" quat="0.707107 0 -0 -0.707107" mesh="hc_r" material="hc_r_material"/>
      <geom type="mesh" class="collision" pos="0.0189667 -0.00869755 -0.0202142" quat="0.707107 0 -0 -0.707107" mesh="hc_r" material="hc_r_material"/>
      <!-- Part base -->
      <geom type="mesh" class="visual" pos="0.0209611 -0.00904543 -0.0222142" quat="0.707107 0 0 -0.707107" mesh="base" material="base_material"/>
      <geom type="mesh" class="collision" pos="0.0209611 -0.00904543 -0.0222142" quat="0.707107 0 0 -0.707107" mesh="base" material="base_material"/>
      <!-- Part hc_c -->
      <geom type="mesh" class="visual" pos="0.0217053 -0.00791173 -0.0202142" quat="0.707107 0 -0 -0.707107" mesh="hc_c" material="hc_c_material"/>
      <geom type="mesh" class="collision" pos="0.0217053 -0.00791173 -0.0202142" quat="0.707107 0 -0 -0.707107" mesh="hc_c" material="hc_c_material"/>
      <!-- Link part_1 -->
      <body name="part_1" pos="-0.060233 -0.0711943 -0.0347142" quat="0 0 0.707107 0.707107">
        <!-- Joint from base to part_1 -->
        <joint axis="0 0 1" name="whell_back" type="hinge"/>
        <inertial pos="0 0 0" mass="1e-09" fullinertia="1e-09 1e-09 1e-09 0 0 0"/>
        <!-- Part part_1_3 -->
        <geom type="mesh" class="visual" pos="0.00424189 0 -0.0129852" quat="0 0 0.707107 0.707107" mesh="part_1__2" material="part_1__2_material"/>
        <geom type="mesh" class="collision" pos="0.00424189 0 -0.0129852" quat="0 0 0.707107 0.707107" mesh="part_1__2" material="part_1__2_material"/>
      </body>
      <!-- Link part_1_2 -->
      <body name="part_1_2" pos="0.102291 0.053669 -0.0347142" quat="0.707107 0.707107 -0 -0">
        <!-- Joint from base to part_1_2 -->
        <joint axis="0 0 1" name="whell_front" type="hinge"/>
        <inertial pos="0 0 0" mass="1e-09" fullinertia="1e-09 1e-09 1e-09 0 0 0"/>
        <!-- Part part_1_4 -->
        <geom type="mesh" class="visual" pos="-0.00424189 0 0.0129852" quat="0.707107 -0.707107 0 0" mesh="part_1__2" material="part_1__2_material"/>
        <geom type="mesh" class="collision" pos="-0.00424189 0 0.0129852" quat="0.707107 -0.707107 0 0" mesh="part_1__2" material="part_1__2_material"/>
      </body>
    </body>
  </worldbody>
  <asset>
    <mesh file="hc_r.stl"/>
    <mesh file="part_1.stl"/>
    <mesh file="hc_l.stl"/>
    <mesh file="base.stl"/>
    <mesh file="part_1__2.stl"/>
    <mesh file="hc_c.stl"/>
    <material name="hc_l_material" rgba="0.231373 0.380392 0.705882 1"/>
    <material name="part_1_material" rgba="0.615686 0.811765 0.929412 1"/>
    <material name="hc_r_material" rgba="0.615686 0.811765 0.929412 1"/>
    <material name="base_material" rgba="0.615686 0.811765 0.929412 1"/>
    <material name="hc_c_material" rgba="0.647059 0.647059 0.647059 1"/>
    <material name="part_1__2_material" rgba="0.615686 0.811765 0.929412 1"/>
  </asset>
  <actuator>
    <velocity name="throttle_back" joint="whell_back" kv="80" gear="0.04" forcelimited="true" forcerange="-300 300"/>
    <velocity name="throttle_front" joint="whell_front" kv="80" gear="0.04" forcelimited="true" forcerange="-300 300"/>
  </actuator>
  <equality/>
</mujoco>
